Workbook
Name WEEKDAY_STAFF: Inputs!$B$26
Name WEEKEND_STAFF: Inputs!$B$27
Name TARGET_MIN: Inputs!$B$28
Name TARGET_MAX: Inputs!$B$29
Name MAX_DAY: Inputs!$B$30
Name BLOCK_MIN: Inputs!$B$31
Name MEAL_MIN: Inputs!$B$32
Name REST_MIN: Inputs!$B$33

Sheet README
A1: Employee Scheduling Tool - README
A3: OVERVIEW
A4: Plans weekly shifts for a business open 7 days/week in 30-minute blocks. You provide employees, operating hours, parameters, and each person's unavailability; the solver fills Schedule and writes Summary.
A6: SHEETS
A7: - Inputs roster, operating hours, tunable parameters.
A8: - Unavailability employees x blocks; mark "X" where unavailable.
A9: - Schedule auto-filled, color-coded per employee.
A10: - Summary paid hours/days/shift lengths, coverage, feasibility.
A12: SET OPERATING HOURS
A13: On Inputs, edit Open/Close per day. Blocks regenerate from these times and SHIFT_BLOCK_MINUTES.
A15: MARK UNAVAILABILITY
A16: On Unavailability, type "X" in any block a person cannot work; blank means available. Cells accept only blank or X; X is shaded red.
... A44: 6. Meal excluded from paid hours; rest included.

Sheet Inputs
A1: Employee Scheduling - Inputs
A3: Employees
A4: Name
A5: Alex
A6: Bina
A7: Cleo
A8: Dario
A14: Operating hours
A15: Day | B15: Open | C15: Close
A16: Mon | B16: 0.29166667 | C16: 0.95833333
A17: Tue | B17: 0.29166667 | C17: 0.95833333
A18: Wed | B18: 0.29166667 | C18: 0.95833333
A19: Thu | B19: 0.29166667 | C19: 0.95833333
A20: Fri | B20: 0.29166667 | C20: 0.95833333
A21: Sat | B21: 0.29166667 | C21: 0.95833333
A22: Sun | B22: 0.29166667 | C22: 0.95833333
A24: Parameters
A25: Parameter | B25: Value
A26: WEEKDAY_STAFF | B26: 2
A27: WEEKEND_STAFF | B27: 2
A28: TARGET_MIN_WEEKLY | B28: 30
A29: TARGET_MAX_WEEKLY | B29: 35
A30: MAX_HOURS_PER_DAY | B30: 8
A31: SHIFT_BLOCK_MINUTES | B31: 30
A32: MEAL_BREAK_MIN | B32: 30
A33: REST_BREAK_MIN | B33: 10
A35: Edit any value above, then re-run schedule_tool.py to refresh the Schedule and Summary sheets. Meal breaks are unpaid (excluded from paid hours); rest breaks are paid (counted as work).

Sheet Unavailability
A1: Unavailability | B1: Mon | AH1: Tue | BN1: Wed | CT1: Thu | DZ1: Fri | FF1: Sat | GL1: Sun
A2: Employee \ Block | B2: 7a | C2: 7:30a | D2: 8a | E2: 8:30a | F2: 9a | G2: 9:30a | H2: 10a | I2: 10:30a | J2: 11a | K2: 11:30a | L2: 12p | M2: 12:30p | N2: 1p | O2: 1:30p | P2: 2p | Q2: 2:30p | R2: 3p | S2: 3:30p | T2: 4p | U2: 4:30p | V2: 5p | W2: 5:30p | X2: 6p | Y2: 6:30p | Z2: 7p | AA2: 7:30p | AB2: 8p | AC2: 8:30p | AD2: 9p | AE2: 9:30p | AF2: 10p | AG2: 10:30p | AH2: 7a | AI2: 7:30a | AJ2: 8a | AK2: 8:30a | AL2: 9a | AM2: 9:30a | AN2: 10a | AO2: 10:30a | AP2: 11a | AQ2: 11:30a | AR2: 12p | AS2: 12:30p | AT2: 1p | AU2: 1:30p | AV2: 2p | AW2: 2:30p | AX2: 3p | AY2: 3:30p | AZ2: 4p | BA2: 4:30p | BB2: 5p | BC2: 5:30p | BD2: 6p | BE2: 6:30p | BF2: 7p | BG2: 7:30p | BH2: 8p | BI2: 8:30p | BJ2: 9p | BK2: 9:30p | BL2: 10p | BM2: 10:30p | BN2: 7a | BO2: 7:30a | BP2: 8a | BQ2: 8:30a | BR2: 9a | BS2: 9:30a | BT2: 10a | BU2: 10:30a | BV2: 11a | BW2: 11:30a | BX2: 12p | BY2: 12:30p | BZ2: 1p | CA2: 1:30p | CB2: 2p | CC2: 2:30p | CD2: 3p | CE2: 3:30p | CF2: 4p | CG2: 4:30p | CH2: 5p | CI2: 5:30p | CJ2: 6p | CK2: 6:30p | CL2: 7p | CM2: 7:30p | CN2: 8p | CO2: 8:30p | CP2: 9p | CQ2: 9:30p | CR2: 10p | CS2: 10:30p | CT2: 7a | CU2: 7:30a | CV2: 8a | CW2: 8:30a | CX2: 9a | CY2: 9:30a | CZ2: 10a | DA2: 10:30a | DB2: 11a | DC2: 11:30a | DD2: 12p | DE2: 12:30p | DF2: 1p | DG2: 1:30p | DH2: 2p | DI2: 2:30p | DJ2: 3p | DK2: 3:30p | DL2: 4p | DM2: 4:30p | DN2: 5p | DO2: 5:30p | DP2: 6p | DQ2: 6:30p | DR2: 7p | DS2: 7:30p | DT2: 8p | DU2: 8:30p | DV2: 9p | DW2: 9:30p | DX2: 10p | DY2: 10:30p | DZ2: 7a | EA2: 7:30a | EB2: 8a | EC2: 8:30a | ED2: 9a | EE2: 9:30a | EF2: 10a | EG2: 10:30a | EH2: 11a | EI2: 11:30a | EJ2: 12p | EK2: 12:30p | EL2: 1p | EM2: 1:30p | EN2: 2p | EO2: 2:30p | EP2: 3p | EQ2: 3:30p | ER2: 4p | ES2: 4:30p | ET2: 5p | EU2: 5:30p | EV2: 6p | EW2: 6:30p | EX2: 7p | EY2: 7:30p | EZ2: 8p | FA2: 8:30p | FB2: 9p | FC2: 9:30p | FD2: 10p | FE2: 10:30p | FF2: 7a | FG2: 7:30a | FH2: 8a | FI2: 8:30a | FJ2: 9a | FK2: 9:30a | FL2: 10a | FM2: 10:30a | FN2: 11a | FO2: 11:30a | FP2: 12p | FQ2: 12:30p | FR2: 1p | FS2: 1:30p | FT2: 2p | FU2: 2:30p | FV2: 3p | FW2: 3:30p | FX2: 4p | FY2: 4:30p | FZ2: 5p | GA2: 5:30p | GB2: 6p | GC2: 6:30p | GD2: 7p | GE2: 7:30p | GF2: 8p | GG2: 8:30p | GH2: 9p | GI2: 9:30p | GJ2: 10p | GK2: 10:30p | GL2: 7a | GM2: 7:30a | GN2: 8a | GO2: 8:30a | GP2: 9a | GQ2: 9:30a | GR2: 10a | GS2: 10:30a | GT2: 11a | GU2: 11:30a | GV2: 12p | GW2: 12:30p | GX2: 1p | GY2: 1:30p | GZ2: 2p | HA2: 2:30p | HB2: 3p | HC2: 3:30p | HD2: 4p | HE2: 4:30p | HF2: 5p | HG2: 5:30p | HH2: 6p | HI2: 6:30p | HJ2: 7p | HK2: 7:30p | HL2: 8p | HM2: 8:30p | HN2: 9p | HO2: 9:30p | HP2: 10p | HQ2: 10:30p
A3: Alex | B3: X | C3: X | D3: X | E3: X | AH3: X | AI3: X | AJ3: X | AK3: X | BN3: X | BO3: X | BP3: X | BQ3: X | CT3: X | CU3: X | CV3: X | CW3: X | DZ3: X | EA3: X | EB3: X | EC3: X | FF3: X | FG3: X | FH3: X | FI3: X | GL3: X | GM3: X | GN3: X | GO3: X
A4: Bina | FF4: X | FG4: X | FH4: X | FI4: X | FJ4: X | FK4: X | FL4: X | FM4: X | FN4: X | FO4: X | FP4: X | FQ4: X | FR4: X | FS4: X | FT4: X | FU4: X | FV4: X | FW4: X | FX4: X | FY4: X | FZ4: X | GA4: X | GB4: X | GC4: X | GD4: X | GE4: X | GF4: X | GG4: X | GH4: X | GI4: X | GJ4: X | GK4: X | GL4: X | GM4: X | GN4: X | GO4: X | GP4: X | GQ4: X | GR4: X | GS4: X | GT4: X | GU4: X | GV4: X | GW4: X | GX4: X | GY4: X | GZ4: X | HA4: X | HB4: X | HC4: X | HD4: X | HE4: X | HF4: X | HG4: X | HH4: X | HI4: X | HJ4: X | HK4: X | HL4: X | HM4: X | HN4: X | HO4: X | HP4: X | HQ4: X
A5: Cleo | AB5: X | AC5: X | AD5: X | AE5: X | AF5: X | AG5: X | BH5: X | BI5: X | BJ5: X | BK5: X | BL5: X | BM5: X | CN5: X | CO5: X | CP5: X | CQ5: X | CR5: X | CS5: X | DT5: X | DU5: X | DV5: X | DW5: X | DX5: X | DY5: X | EZ5: X | FA5: X | FB5: X | FC5: X | FD5: X | FE5: X | GF5: X | GG5: X | GH5: X | GI5: X | GJ5: X | GK5: X | HL5: X | HM5: X | HN5: X | HO5: X | HP5: X | HQ5: X
A6: Dario | B6: X | C6: X | D6: X | E6: X | F6: X | G6: X | H6: X | I6: X | BN6: X | BO6: X | BP6: X | BQ6: X | BR6: X | BS6: X | BT6: X | BU6: X | BV6: X | BW6: X | BX6: X | BY6: X | BZ6: X | CA6: X | CB6: X | CC6: X | CD6: X | CE6: X | CF6: X | CG6: X | CH6: X | CI6: X | CJ6: X | CK6: X | CL6: X | CM6: X | CN6: X | CO6: X | CP6: X | CQ6: X | CR6: X | CS6: X
A8: Mark "X" where an employee is NOT available; blank = available. Re-run schedule_tool.py after editing.

Sheet Schedule
A1: Schedule | B1: Mon | AH1: Tue | BN1: Wed | CT1: Thu | DZ1: Fri | FF1: Sat | GL1: Sun
A2: Employee \ Block | B2: 7a | C2: 7:30a | D2: 8a | E2: 8:30a | F2: 9a | G2: 9:30a | H2: 10a | I2: 10:30a | J2: 11a | K2: 11:30a | L2: 12p | M2: 12:30p | N2: 1p | O2: 1:30p | P2: 2p | Q2: 2:30p | R2: 3p | S2: 3:30p | T2: 4p | U2: 4:30p | V2: 5p | W2: 5:30p | X2: 6p | Y2: 6:30p | Z2: 7p | AA2: 7:30p | AB2: 8p | AC2: 8:30p | AD2: 9p | AE2: 9:30p | AF2: 10p | AG2: 10:30p | AH2: 7a | AI2: 7:30a | AJ2: 8a | AK2: 8:30a | AL2: 9a | AM2: 9:30a | AN2: 10a | AO2: 10:30a | AP2: 11a | AQ2: 11:30a | AR2: 12p | AS2: 12:30p | AT2: 1p | AU2: 1:30p | AV2: 2p | AW2: 2:30p | AX2: 3p | AY2: 3:30p | AZ2: 4p | BA2: 4:30p | BB2: 5p | BC2: 5:30p | BD2: 6p | BE2: 6:30p | BF2: 7p | BG2: 7:30p | BH2: 8p | BI2: 8:30p | BJ2: 9p | BK2: 9:30p | BL2: 10p | BM2: 10:30p | BN2: 7a | BO2: 7:30a | BP2: 8a | BQ2: 8:30a | BR2: 9a | BS2: 9:30a | BT2: 10a | BU2: 10:30a | BV2: 11a | BW2: 11:30a | BX2: 12p | BY2: 12:30p | BZ2: 1p | CA2: 1:30p | CB2: 2p | CC2: 2:30p | CD2: 3p | CE2: 3:30p | CF2: 4p | CG2: 4:30p | CH2: 5p | CI2: 5:30p | CJ2: 6p | CK2: 6:30p | CL2: 7p | CM2: 7:30p | CN2: 8p | CO2: 8:30p | CP2: 9p | CQ2: 9:30p | CR2: 10p | CS2: 10:30p | CT2: 7a | CU2: 7:30a | CV2: 8a | CW2: 8:30a | CX2: 9a | CY2: 9:30a | CZ2: 10a | DA2: 10:30a | DB2: 11a | DC2: 11:30a | DD2: 12p | DE2: 12:30p | DF2: 1p | DG2: 1:30p | DH2: 2p | DI2: 2:30p | DJ2: 3p | DK2: 3:30p | DL2: 4p | DM2: 4:30p | DN2: 5p | DO2: 5:30p | DP2: 6p | DQ2: 6:30p | DR2: 7p | DS2: 7:30p | DT2: 8p | DU2: 8:30p | DV2: 9p | DW2: 9:30p | DX2: 10p | DY2: 10:30p | DZ2: 7a | EA2: 7:30a | EB2: 8a | EC2: 8:30a | ED2: 9a | EE2: 9:30a | EF2: 10a | EG2: 10:30a | EH2: 11a | EI2: 11:30a | EJ2: 12p | EK2: 12:30p | EL2: 1p | EM2: 1:30p | EN2: 2p | EO2: 2:30p | EP2: 3p | EQ2: 3:30p | ER2: 4p | ES2: 4:30p | ET2: 5p | EU2: 5:30p | EV2: 6p | EW2: 6:30p | EX2: 7p | EY2: 7:30p | EZ2: 8p | FA2: 8:30p | FB2: 9p | FC2: 9:30p | FD2: 10p | FE2: 10:30p | FF2: 7a | FG2: 7:30a | FH2: 8a | FI2: 8:30a | FJ2: 9a | FK2: 9:30a | FL2: 10a | FM2: 10:30a | FN2: 11a | FO2: 11:30a | FP2: 12p | FQ2: 12:30p | FR2: 1p | FS2: 1:30p | FT2: 2p | FU2: 2:30p | FV2: 3p | FW2: 3:30p | FX2: 4p | FY2: 4:30p | FZ2: 5p | GA2: 5:30p | GB2: 6p | GC2: 6:30p | GD2: 7p | GE2: 7:30p | GF2: 8p | GG2: 8:30p | GH2: 9p | GI2: 9:30p | GJ2: 10p | GK2: 10:30p | GL2: 7a | GM2: 7:30a | GN2: 8a | GO2: 8:30a | GP2: 9a | GQ2: 9:30a | GR2: 10a | GS2: 10:30a | GT2: 11a | GU2: 11:30a | GV2: 12p | GW2: 12:30p | GX2: 1p | GY2: 1:30p | GZ2: 2p | HA2: 2:30p | HB2: 3p | HC2: 3:30p | HD2: 4p | HE2: 4:30p | HF2: 5p | HG2: 5:30p | HH2: 6p | HI2: 6:30p | HJ2: 7p | HK2: 7:30p | HL2: 8p | HM2: 8:30p | HN2: 9p | HO2: 9:30p | HP2: 10p | HQ2: 10:30p
A3: Alex | B3: · | C3: · | D3: · | E3: · | F3: ● | G3: ● | H3: ● | I3: ● | J3: ● | K3: R | L3: ● | M3: ● | N3: M | O3: ● | P3: ● | Q3: R | R3: ● | S3: ● | T3: ● | U3: ● | V3: ● | AH3: · | AI3: · | AJ3: · | AK3: · | AP3: ● | BN3: · | BO3: · | BP3: · | BQ3: · | BR3: ● | BS3: ● | BT3: ● | BU3: ● | BV3: ● | BW3: R | BX3: ● | BY3: ● | BZ3: M | CA3: ● | CB3: ● | CC3: R | CD3: ● | CE3: ● | CF3: ● | CG3: ● | CH3: ● | CT3: · | CU3: · | CV3: · | CW3: · | CX3: ● | CY3: ● | CZ3: ● | DA3: ● | DB3: ● | DC3: R | DD3: ● | DE3: ● | DF3: M | DG3: ● | DH3: ● | DI3: R | DJ3: ● | DK3: ● | DL3: ● | DM3: ● | DN3: ● | DZ3: · | EA3: · | EB3: · | EC3: · | EN3: ● | EO3: ● | EP3: ● | EQ3: ● | ER3: ● | ES3: R | ET3: ● | EU3: ● | EV3: M | EW3: ● | EX3: ● | EY3: R | EZ3: ● | FA3: ● | FB3: ● | FC3: ● | FD3: ● | FF3: · | FG3: · | FH3: · | FI3: · | FW3: ● | FX3: ● | FY3: R | FZ3: ● | GA3: ● | GL3: · | GM3: · | GN3: · | GO3: ·
A4: Bina | B4: ● | C4: ● | D4: ● | E4: ● | F4: ● | G4: R | H4: ● | I4: ● | J4: M | K4: ● | L4: ● | M4: R | N4: ● | O4: ● | P4: ● | Q4: ● | R4: ● | AH4: ● | AI4: ● | AJ4: ● | AK4: ● | AL4: ● | AM4: R | AN4: M | AO4: ● | AP4: ● | AQ4: ● | AR4: ● | AS4: ● | BN4: ● | BO4: ● | BP4: ● | BQ4: ● | BR4: ● | BS4: R | BT4: ● | BU4: ● | BV4: M | BW4: ● | BX4: ● | BY4: R | BZ4: ● | CA4: ● | CB4: ● | CC4: ● | CD4: ● | CT4: ● | DZ4: ● | EA4: ● | EB4: ● | EC4: ● | ED4: ● | EE4: R | EF4: ● | EG4: ● | EH4: M | EI4: ● | EJ4: ● | EK4: R | EL4: ● | EM4: ● | EN4: ● | EO4: ● | EP4: ● | FF4: · | FG4: · | FH4: · | FI4: · | FJ4: · | FK4: · | FL4: · | FM4: · | FN4: · | FO4: · | FP4: · | FQ4: · | FR4: · | FS4: · | FT4: · | FU4: · | FV4: · | FW4: · | FX4: · | FY4: · | FZ4: · | GA4: · | GB4: · | GC4: · | GD4: · | GE4: · | GF4: · | GG4: · | GH4: · | GI4: · | GJ4: · | GK4: · | GL4: · | GM4: · | GN4: · | GO4: · | GP4: · | GQ4: · | GR4: · | GS4: · | GT4: · | GU4: · | GV4: · | GW4: · | GX4: · | GY4: · | GZ4: · | HA4: · | HB4: · | HC4: · | HD4: · | HE4: · | HF4: · | HG4: · | HH4: · | HI4: · | HJ4: · | HK4: · | HL4: · | HM4: · | HN4: · | HO4: · | HP4: · | HQ4: ·
A5: Cleo | B5: ● | C5: ● | D5: R | E5: ● | AB5: · | AC5: · | AD5: · | AE5: · | AF5: · | AG5: · | AH5: ● | AI5: ● | AJ5: ● | AK5: ● | AL5: ● | AM5: R | AN5: ● | AO5: ● | AP5: M | AQ5: ● | AR5: ● | AS5: R | AT5: ● | AU5: ● | AV5: ● | AW5: ● | AX5: ● | BH5: · | BI5: · | BJ5: · | BK5: · | BL5: · | BM5: · | BN5: ● | BO5: ● | BP5: R | BQ5: ● | CN5: · | CO5: · | CP5: · | CQ5: · | CR5: · | CS5: · | CT5: ● | CU5: ● | CV5: ● | CW5: ● | CX5: ● | CY5: R | CZ5: ● | DA5: ● | DB5: M | DC5: ● | DD5: ● | DE5: R | DF5: ● | DG5: ● | DH5: ● | DI5: ● | DJ5: ● | DT5: · | DU5: · | DV5: · | DW5: · | DX5: · | DY5: · | EE5: ● | EF5: ● | EG5: ● | EH5: ● | EI5: R | EJ5: ● | EK5: ● | EL5: ● | EM5: ● | EZ5: · | FA5: · | FB5: · | FC5: · | FD5: · | FE5: · | FF5: ● | FG5: ● | FH5: ● | FI5: ● | FJ5: ● | FK5: R | FL5: ● | FM5: ● | FN5: M | FO5: ● | FP5: ● | FQ5: R | FR5: ● | FS5: ● | FT5: ● | FU5: ● | FV5: ● | GF5: · | GG5: · | GH5: · | GI5: · | GJ5: · | GK5: · | GL5: ● | GM5: ● | GN5: R | GO5: ● | GP5: ● | HL5: · | HM5: · | HN5: · | HO5: · | HP5: · | HQ5: ·
A6: Dario | B6: · | C6: · | D6: · | E6: · | F6: · | G6: · | H6: · | I6: · | J6: ● | K6: ● | L6: ● | M6: ● | N6: ● | O6: R | P6: ● | Q6: ● | R6: M | S6: ● | T6: ● | U6: R | V6: ● | W6: ● | X6: ● | Y6: ● | Z6: ● | AQ6: ● | AR6: ● | AS6: ● | AT6: ● | AU6: ● | AV6: R | AW6: ● | AX6: ● | AY6: M | AZ6: ● | BA6: ● | BB6: R | BC6: ● | BD6: ● | BE6: ● | BF6: ● | BG6: ● | BN6: · | BO6: · | BP6: · | BQ6: · | BR6: · | BS6: · | BT6: · | BU6: · | BV6: · | BW6: · | BX6: · | BY6: · | BZ6: · | CA6: · | CB6: · | CC6: · | CD6: · | CE6: · | CF6: · | CG6: · | CH6: · | CI6: · | CJ6: · | CK6: · | CL6: · | CM6: · | CN6: · | CO6: · | CP6: · | CQ6: · | CR6: · | CS6: · | CU6: ● | CV6: ● | CW6: ● | DZ6: ● | EA6: ● | EB6: R | EC6: ● | ED6: ● | FF6: ● | FG6: ● | FH6: ● | FI6: ● | FJ6: ● | FK6: R | FL6: ● | FM6: ● | FN6: M | FO6: ● | FP6: ● | FQ6: R | FR6: ● | FS6: ● | FT6: ● | FU6: ● | FV6: ● | GL6: ● | GM6: ● | GN6: ● | GO6: ● | GP6: R | GQ6: ● | GR6: ● | GS6: M | GT6: ● | GU6: ● | GV6: R | GW6: ● | GX6: ● | GY6: ● | GZ6: ●
A7: Scheduled | B7: 2 | C7: 2 | D7: 2 | E7: 2 | F7: 2 | G7: 2 | H7: 2 | I7: 2 | J7: 2 | K7: 3 | L7: 3 | M7: 3 | N7: 2 | O7: 3 | P7: 3 | Q7: 3 | R7: 2 | S7: 2 | T7: 2 | U7: 2 | V7: 2 | W7: 1 | X7: 1 | Y7: 1 | Z7: 1 | AA7: 0 | AB7: 0 | AC7: 0 | AD7: 0 | AE7: 0 | AF7: 0 | AG7: 0 | AH7: 2 | AI7: 2 | AJ7: 2 | AK7: 2 | AL7: 2 | AM7: 2 | AN7: 1 | AO7: 2 | AP7: 2 | AQ7: 3 | AR7: 3 | AS7: 3 | AT7: 2 | AU7: 2 | AV7: 2 | AW7: 2 | AX7: 2 | AY7: 0 | AZ7: 1 | BA7: 1 | BB7: 1 | BC7: 1 | BD7: 1 | BE7: 1 | BF7: 1 | BG7: 1 | BH7: 0 | BI7: 0 | BJ7: 0 | BK7: 0 | BL7: 0 | BM7: 0 | BN7: 2 | BO7: 2 | BP7: 2 | BQ7: 2 | BR7: 2 | BS7: 2 | BT7: 2 | BU7: 2 | BV7: 1 | BW7: 2 | BX7: 2 | BY7: 2 | BZ7: 1 | CA7: 2 | CB7: 2 | CC7: 2 | CD7: 2 | CE7: 1 | CF7: 1 | CG7: 1 | CH7: 1 | CI7: 0 | CJ7: 0 | CK7: 0 | CL7: 0 | CM7: 0 | CN7: 0 | CO7: 0 | CP7: 0 | CQ7: 0 | CR7: 0 | CS7: 0 | CT7: 2 | CU7: 2 | CV7: 2 | CW7: 2 | CX7: 2 | CY7: 2 | CZ7: 2 | DA7: 2 | DB7: 1 | DC7: 2 | DD7: 2 | DE7: 2 | DF7: 1 | DG7: 2 | DH7: 2 | DI7: 2 | DJ7: 2 | DK7: 1 | DL7: 1 | DM7: 1 | DN7: 1 | DO7: 0 | DP7: 0 | DQ7: 0 | DR7: 0 | DS7: 0 | DT7: 0 | DU7: 0 | DV7: 0 | DW7: 0 | DX7: 0 | DY7: 0 | DZ7: 2 | EA7: 2 | EB7: 2 | EC7: 2 | ED7: 2 | EE7: 2 | EF7: 2 | EG7: 2 | EH7: 1 | EI7: 2 | EJ7: 2 | EK7: 2 | EL7: 2 | EM7: 2 | EN7: 2 | EO7: 2 | EP7: 2 | EQ7: 1 | ER7: 1 | ES7: 1 | ET7: 1 | EU7: 1 | EV7: 0 | EW7: 1 | EX7: 1 | EY7: 1 | EZ7: 1 | FA7: 1 | FB7: 1 | FC7: 1 | FD7: 1 | FE7: 0 | FF7: 2 | FG7: 2 | FH7: 2 | FI7: 2 | FJ7: 2 | FK7: 2 | FL7: 2 | FM7: 2 | FN7: 0 | FO7: 2 | FP7: 2 | FQ7: 2 | FR7: 2 | FS7: 2 | FT7: 2 | FU7: 2 | FV7: 2 | FW7: 1 | FX7: 1 | FY7: 1 | FZ7: 1 | GA7: 1 | GB7: 0 | GC7: 0 | GD7: 0 | GE7: 0 | GF7: 0 | GG7: 0 | GH7: 0 | GI7: 0 | GJ7: 0 | GK7: 0 | GL7: 2 | GM7: 2 | GN7: 2 | GO7: 2 | GP7: 2 | GQ7: 1 | GR7: 1 | GS7: 0 | GT7: 1 | GU7: 1 | GV7: 1 | GW7: 1 | GX7: 1 | GY7: 1 | GZ7: 1 | HA7: 0 | HB7: 0 | HC7: 0 | HD7: 0 | HE7: 0 | HF7: 0 | HG7: 0 | HH7: 0 | HI7: 0 | HJ7: 0 | HK7: 0 | HL7: 0 | HM7: 0 | HN7: 0 | HO7: 0 | HP7: 0 | HQ7: 0
A8: Required | B8: 2 | C8: 2 | D8: 2 | E8: 2 | F8: 2 | G8: 2 | H8: 2 | I8: 2 | J8: 2 | K8: 2 | L8: 2 | M8: 2 | N8: 2 | O8: 2 | P8: 2 | Q8: 2 | R8: 2 | S8: 2 | T8: 2 | U8: 2 | V8: 2 | W8: 2 | X8: 2 | Y8: 2 | Z8: 2 | AA8: 2 | AB8: 2 | AC8: 2 | AD8: 2 | AE8: 2 | AF8: 2 | AG8: 2 | AH8: 2 | AI8: 2 | AJ8: 2 | AK8: 2 | AL8: 2 | AM8: 2 | AN8: 2 | AO8: 2 | AP8: 2 | AQ8: 2 | AR8: 2 | AS8: 2 | AT8: 2 | AU8: 2 | AV8: 2 | AW8: 2 | AX8: 2 | AY8: 2 | AZ8: 2 | BA8: 2 | BB8: 2 | BC8: 2 | BD8: 2 | BE8: 2 | BF8: 2 | BG8: 2 | BH8: 2 | BI8: 2 | BJ8: 2 | BK8: 2 | BL8: 2 | BM8: 2 | BN8: 2 | BO8: 2 | BP8: 2 | BQ8: 2 | BR8: 2 | BS8: 2 | BT8: 2 | BU8: 2 | BV8: 2 | BW8: 2 | BX8: 2 | BY8: 2 | BZ8: 2 | CA8: 2 | CB8: 2 | CC8: 2 | CD8: 2 | CE8: 2 | CF8: 2 | CG8: 2 | CH8: 2 | CI8: 2 | CJ8: 2 | CK8: 2 | CL8: 2 | CM8: 2 | CN8: 2 | CO8: 2 | CP8: 2 | CQ8: 2 | CR8: 2 | CS8: 2 | CT8: 2 | CU8: 2 | CV8: 2 | CW8: 2 | CX8: 2 | CY8: 2 | CZ8: 2 | DA8: 2 | DB8: 2 | DC8: 2 | DD8: 2 | DE8: 2 | DF8: 2 | DG8: 2 | DH8: 2 | DI8: 2 | DJ8: 2 | DK8: 2 | DL8: 2 | DM8: 2 | DN8: 2 | DO8: 2 | DP8: 2 | DQ8: 2 | DR8: 2 | DS8: 2 | DT8: 2 | DU8: 2 | DV8: 2 | DW8: 2 | DX8: 2 | DY8: 2 | DZ8: 2 | EA8: 2 | EB8: 2 | EC8: 2 | ED8: 2 | EE8: 2 | EF8: 2 | EG8: 2 | EH8: 2 | EI8: 2 | EJ8: 2 | EK8: 2 | EL8: 2 | EM8: 2 | EN8: 2 | EO8: 2 | EP8: 2 | EQ8: 2 | ER8: 2 | ES8: 2 | ET8: 2 | EU8: 2 | EV8: 2 | EW8: 2 | EX8: 2 | EY8: 2 | EZ8: 2 | FA8: 2 | FB8: 2 | FC8: 2 | FD8: 2 | FE8: 2 | FF8: 2 | FG8: 2 | FH8: 2 | FI8: 2 | FJ8: 2 | FK8: 2 | FL8: 2 | FM8: 2 | FN8: 2 | FO8: 2 | FP8: 2 | FQ8: 2 | FR8: 2 | FS8: 2 | FT8: 2 | FU8: 2 | FV8: 2 | FW8: 2 | FX8: 2 | FY8: 2 | FZ8: 2 | GA8: 2 | GB8: 2 | GC8: 2 | GD8: 2 | GE8: 2 | GF8: 2 | GG8: 2 | GH8: 2 | GI8: 2 | GJ8: 2 | GK8: 2 | GL8: 2 | GM8: 2 | GN8: 2 | GO8: 2 | GP8: 2 | GQ8: 2 | GR8: 2 | GS8: 2 | GT8: 2 | GU8: 2 | GV8: 2 | GW8: 2 | GX8: 2 | GY8: 2 | GZ8: 2 | HA8: 2 | HB8: 2 | HC8: 2 | HD8: 2 | HE8: 2 | HF8: 2 | HG8: 2 | HH8: 2 | HI8: 2 | HJ8: 2 | HK8: 2 | HL8: 2 | HM8: 2 | HN8: 2 | HO8: 2 | HP8: 2 | HQ8: 2
A10: Legend
A11: Alex (work ●)
A12: Bina (work ●)
A13: Cleo (work ●)
A14: Dario (work ●)
A15: Rest break (R) - paid
A16: Meal break (M) - unpaid
A17: Unavailable

Sheet Summary
A1: Schedule Summary
A3: Per-employee totals (paid hours)
A4: Employee | B4: Paid hours | C4: Days worked | D4: Status | E4: Shift lengths (paid h)
A5: Alex | B5: =(COUNTIF(Schedule!B3:HQ3,"●")+COUNTIF(Schedule!B3:HQ3,"R"))*(BLOCK_MIN/60) | C5: =((COUNTIF(Schedule!B3:AG3,"●")+COUNTIF(Schedule!B3:AG3,"R"))>0)+((COUNTIF(Schedule!AH3:BM3,"●")+COUNTIF(Schedule!AH3:BM3,"R"))>0)+((COUNTIF(Schedule!BN3:CS3,"●")+COUNTIF(Schedule!BN3:CS3,"R"))>0)+((COUNTIF(Schedule!CT3:DY3,"●")+COUNTIF(Schedule!CT3:DY3,"R"))>0)+((COUNTIF(Schedule!DZ3:FE3,"●")+COUNTIF(Schedule!DZ3:FE3,"R"))>0)+((COUNTIF(Schedule!FF3:GK3,"●")+COUNTIF(Schedule!FF3:GK3,"R"))>0)+((COUNTIF(Schedule!GL3:HQ3,"●")+COUNTIF(Schedule!GL3:HQ3,"R"))>0) | D5: =IF(B5<TARGET_MIN,"BELOW MIN",IF(B5>TARGET_MAX,"ABOVE MAX",IF((MAX((COUNTIF(Schedule!B3:AG3,"●")+COUNTIF(Schedule!B3:AG3,"R")),(COUNTIF(Schedule!AH3:BM3,"●")+COUNTIF(Schedule!AH3:BM3,"R")),(COUNTIF(Schedule!BN3:CS3,"●")+COUNTIF(Schedule!BN3:CS3,"R")),(COUNTIF(Schedule!CT3:DY3,"●")+COUNTIF(Schedule!CT3:DY3,"R")),(COUNTIF(Schedule!DZ3:FE3,"●")+COUNTIF(Schedule!DZ3:FE3,"R")),(COUNTIF(Schedule!FF3:GK3,"●")+COUNTIF(Schedule!FF3:GK3,"R")),(COUNTIF(Schedule!GL3:HQ3,"●")+COUNTIF(Schedule!GL3:HQ3,"R")))*(BLOCK_MIN/60))>MAX_DAY,"OVER DAILY CAP","OK"))) | E5: Mon 8, Tue 0.5, Wed 8, Thu 8, Fri 8, Sat 2.5
A6: Bina | B6: =(COUNTIF(Schedule!B4:HQ4,"●")+COUNTIF(Schedule!B4:HQ4,"R"))*(BLOCK_MIN/60) | C6: =((COUNTIF(Schedule!B4:AG4,"●")+COUNTIF(Schedule!B4:AG4,"R"))>0)+((COUNTIF(Schedule!AH4:BM4,"●")+COUNTIF(Schedule!AH4:BM4,"R"))>0)+((COUNTIF(Schedule!BN4:CS4,"●")+COUNTIF(Schedule!BN4:CS4,"R"))>0)+((COUNTIF(Schedule!CT4:DY4,"●")+COUNTIF(Schedule!CT4:DY4,"R"))>0)+((COUNTIF(Schedule!DZ4:FE4,"●")+COUNTIF(Schedule!DZ4:FE4,"R"))>0)+((COUNTIF(Schedule!FF4:GK4,"●")+COUNTIF(Schedule!FF4:GK4,"R"))>0)+((COUNTIF(Schedule!GL4:HQ4,"●")+COUNTIF(Schedule!GL4:HQ4,"R"))>0) | D6: =IF(B6<TARGET_MIN,"BELOW MIN",IF(B6>TARGET_MAX,"ABOVE MAX",IF((MAX((COUNTIF(Schedule!B4:AG4,"●")+COUNTIF(Schedule!B4:AG4,"R")),(COUNTIF(Schedule!AH4:BM4,"●")+COUNTIF(Schedule!AH4:BM4,"R")),(COUNTIF(Schedule!BN4:CS4,"●")+COUNTIF(Schedule!BN4:CS4,"R")),(COUNTIF(Schedule!CT4:DY4,"●")+COUNTIF(Schedule!CT4:DY4,"R")),(COUNTIF(Schedule!DZ4:FE4,"●")+COUNTIF(Schedule!DZ4:FE4,"R")),(COUNTIF(Schedule!FF4:GK4,"●")+COUNTIF(Schedule!FF4:GK4,"R")),(COUNTIF(Schedule!GL4:HQ4,"●")+COUNTIF(Schedule!GL4:HQ4,"R")))*(BLOCK_MIN/60))>MAX_DAY,"OVER DAILY CAP","OK"))) | E6: Mon 8, Tue 5.5, Wed 8, Thu 0.5, Fri 8
A7: Cleo | B7: =(COUNTIF(Schedule!B5:HQ5,"●")+COUNTIF(Schedule!B5:HQ5,"R"))*(BLOCK_MIN/60) | C7: =((COUNTIF(Schedule!B5:AG5,"●")+COUNTIF(Schedule!B5:AG5,"R"))>0)+((COUNTIF(Schedule!AH5:BM5,"●")+COUNTIF(Schedule!AH5:BM5,"R"))>0)+((COUNTIF(Schedule!BN5:CS5,"●")+COUNTIF(Schedule!BN5:CS5,"R"))>0)+((COUNTIF(Schedule!CT5:DY5,"●")+COUNTIF(Schedule!CT5:DY5,"R"))>0)+((COUNTIF(Schedule!DZ5:FE5,"●")+COUNTIF(Schedule!DZ5:FE5,"R"))>0)+((COUNTIF(Schedule!FF5:GK5,"●")+COUNTIF(Schedule!FF5:GK5,"R"))>0)+((COUNTIF(Schedule!GL5:HQ5,"●")+COUNTIF(Schedule!GL5:HQ5,"R"))>0) | D7: =IF(B7<TARGET_MIN,"BELOW MIN",IF(B7>TARGET_MAX,"ABOVE MAX",IF((MAX((COUNTIF(Schedule!B5:AG5,"●")+COUNTIF(Schedule!B5:AG5,"R")),(COUNTIF(Schedule!AH5:BM5,"●")+COUNTIF(Schedule!AH5:BM5,"R")),(COUNTIF(Schedule!BN5:CS5,"●")+COUNTIF(Schedule!BN5:CS5,"R")),(COUNTIF(Schedule!CT5:DY5,"●")+COUNTIF(Schedule!CT5:DY5,"R")),(COUNTIF(Schedule!DZ5:FE5,"●")+COUNTIF(Schedule!DZ5:FE5,"R")),(COUNTIF(Schedule!FF5:GK5,"●")+COUNTIF(Schedule!FF5:GK5,"R")),(COUNTIF(Schedule!GL5:HQ5,"●")+COUNTIF(Schedule!GL5:HQ5,"R")))*(BLOCK_MIN/60))>MAX_DAY,"OVER DAILY CAP","OK"))) | E7: Mon 2, Tue 8, Wed 2, Thu 8, Fri 4.5, Sat 8, Sun 2.5
A8: Dario | B8: =(COUNTIF(Schedule!B6:HQ6,"●")+COUNTIF(Schedule!B6:HQ6,"R"))*(BLOCK_MIN/60) | C8: =((COUNTIF(Schedule!B6:AG6,"●")+COUNTIF(Schedule!B6:AG6,"R"))>0)+((COUNTIF(Schedule!AH6:BM6,"●")+COUNTIF(Schedule!AH6:BM6,"R"))>0)+((COUNTIF(Schedule!BN6:CS6,"●")+COUNTIF(Schedule!BN6:CS6,"R"))>0)+((COUNTIF(Schedule!CT6:DY6,"●")+COUNTIF(Schedule!CT6:DY6,"R"))>0)+((COUNTIF(Schedule!DZ6:FE6,"●")+COUNTIF(Schedule!DZ6:FE6,"R"))>0)+((COUNTIF(Schedule!FF6:GK6,"●")+COUNTIF(Schedule!FF6:GK6,"R"))>0)+((COUNTIF(Schedule!GL6:HQ6,"●")+COUNTIF(Schedule!GL6:HQ6,"R"))>0) | D8: =IF(B8<TARGET_MIN,"BELOW MIN",IF(B8>TARGET_MAX,"ABOVE MAX",IF((MAX((COUNTIF(Schedule!B6:AG6,"●")+COUNTIF(Schedule!B6:AG6,"R")),(COUNTIF(Schedule!AH6:BM6,"●")+COUNTIF(Schedule!AH6:BM6,"R")),(COUNTIF(Schedule!BN6:CS6,"●")+COUNTIF(Schedule!BN6:CS6,"R")),(COUNTIF(Schedule!CT6:DY6,"●")+COUNTIF(Schedule!CT6:DY6,"R")),(COUNTIF(Schedule!DZ6:FE6,"●")+COUNTIF(Schedule!DZ6:FE6,"R")),(COUNTIF(Schedule!FF6:GK6,"●")+COUNTIF(Schedule!FF6:GK6,"R")),(COUNTIF(Schedule!GL6:HQ6,"●")+COUNTIF(Schedule!GL6:HQ6,"R")))*(BLOCK_MIN/60))>MAX_DAY,"OVER DAILY CAP","OK"))) | E8: Mon 8, Tue 8, Thu 1.5, Fri 2.5, Sat 8, Sun 7
A10: Coverage per time block
A11: Day | B11: Time | C11: Scheduled | D11: Required | E11: Status
A12: Mon | B12: 7:00 AM | C12: =COUNTIF(Schedule!B3:B6,"●")+COUNTIF(Schedule!B3:B6,"R") | D12: =WEEKDAY_STAFF | E12: =IF(C12<D12,"UNCOVERED","ok")
A13: Mon | B13: 7:30 AM | C13: =COUNTIF(Schedule!C3:C6,"●")+COUNTIF(Schedule!C3:C6,"R") | D13: =WEEKDAY_STAFF | E13: =IF(C13<D13,"UNCOVERED","ok")
A14: Mon | B14: 8:00 AM | C14: =COUNTIF(Schedule!D3:D6,"●")+COUNTIF(Schedule!D3:D6,"R") | D14: =WEEKDAY_STAFF | E14: =IF(C14<D14,"UNCOVERED","ok")
A15: Mon | B15: 8:30 AM | C15: =COUNTIF(Schedule!E3:E6,"●")+COUNTIF(Schedule!E3:E6,"R") | D15: =WEEKDAY_STAFF | E15: =IF(C15<D15,"UNCOVERED","ok")
A16: Mon | B16: 9:00 AM | C16: =COUNTIF(Schedule!F3:F6,"●")+COUNTIF(Schedule!F3:F6,"R") | D16: =WEEKDAY_STAFF | E16: =IF(C16<D16,"UNCOVERED","ok")
A17: Mon | B17: 9:30 AM | C17: =COUNTIF(Schedule!G3:G6,"●")+COUNTIF(Schedule!G3:G6,"R") | D17: =WEEKDAY_STAFF | E17: =IF(C17<D17,"UNCOVERED","ok")
A18: Mon | B18: 10:00 AM | C18: =COUNTIF(Schedule!H3:H6,"●")+COUNTIF(Schedule!H3:H6,"R") | D18: =WEEKDAY_STAFF | E18: =IF(C18<D18,"UNCOVERED","ok")
A19: Mon | B19: 10:30 AM | C19: =COUNTIF(Schedule!I3:I6,"●")+COUNTIF(Schedule!I3:I6,"R") | D19: =WEEKDAY_STAFF | E19: =IF(C19<D19,"UNCOVERED","ok")
A20: Mon | B20: 11:00 AM | C20: =COUNTIF(Schedule!J3:J6,"●")+COUNTIF(Schedule!J3:J6,"R") | D20: =WEEKDAY_STAFF | E20: =IF(C20<D20,"UNCOVERED","ok")
A21: Mon | B21: 11:30 AM | C21: =COUNTIF(Schedule!K3:K6,"●")+COUNTIF(Schedule!K3:K6,"R") | D21: =WEEKDAY_STAFF | E21: =IF(C21<D21,"UNCOVERED","ok")
A22: Mon | B22: 12:00 PM | C22: =COUNTIF(Schedule!L3:L6,"●")+COUNTIF(Schedule!L3:L6,"R") | D22: =WEEKDAY_STAFF | E22: =IF(C22<D22,"UNCOVERED","ok")
A23: Mon | B23: 12:30 PM | C23: =COUNTIF(Schedule!M3:M6,"●")+COUNTIF(Schedule!M3:M6,"R") | D23: =WEEKDAY_STAFF | E23: =IF(C23<D23,"UNCOVERED","ok")
A24: Mon | B24: 1:00 PM | C24: =COUNTIF(Schedule!N3:N6,"●")+COUNTIF(Schedule!N3:N6,"R") | D24: =WEEKDAY_STAFF | E24: =IF(C24<D24,"UNCOVERED","ok")
A25: Mon | B25: 1:30 PM | C25: =COUNTIF(Schedule!O3:O6,"●")+COUNTIF(Schedule!O3:O6,"R") | D25: =WEEKDAY_STAFF | E25: =IF(C25<D25,"UNCOVERED","ok")
A26: Mon | B26: 2:00 PM | C26: =COUNTIF(Schedule!P3:P6,"●")+COUNTIF(Schedule!P3:P6,"R") | D26: =WEEKDAY_STAFF | E26: =IF(C26<D26,"UNCOVERED","ok")
A27: Mon | B27: 2:30 PM | C27: =COUNTIF(Schedule!Q3:Q6,"●")+COUNTIF(Schedule!Q3:Q6,"R") | D27: =WEEKDAY_STAFF | E27: =IF(C27<D27,"UNCOVERED","ok")
A28: Mon | B28: 3:00 PM | C28: =COUNTIF(Schedule!R3:R6,"●")+COUNTIF(Schedule!R3:R6,"R") | D28: =WEEKDAY_STAFF | E28: =IF(C28<D28,"UNCOVERED","ok")
A29: Mon | B29: 3:30 PM | C29: =COUNTIF(Schedule!S3:S6,"●")+COUNTIF(Schedule!S3:S6,"R") | D29: =WEEKDAY_STAFF | E29: =IF(C29<D29,"UNCOVERED","ok")
A30: Mon | B30: 4:00 PM | C30: =COUNTIF(Schedule!T3:T6,"●")+COUNTIF(Schedule!T3:T6,"R") | D30: =WEEKDAY_STAFF | E30: =IF(C30<D30,"UNCOVERED","ok")
A31: Mon | B31: 4:30 PM | C31: =COUNTIF(Schedule!U3:U6,"●")+COUNTIF(Schedule!U3:U6,"R") | D31: =WEEKDAY_STAFF | E31: =IF(C31<D31,"UNCOVERED","ok")
A32: Mon | B32: 5:00 PM | C32: =COUNTIF(Schedule!V3:V6,"●")+COUNTIF(Schedule!V3:V6,"R") | D32: =WEEKDAY_STAFF | E32: =IF(C32<D32,"UNCOVERED","ok")
A33: Mon | B33: 5:30 PM | C33: =COUNTIF(Schedule!W3:W6,"●")+COUNTIF(Schedule!W3:W6,"R") | D33: =WEEKDAY_STAFF | E33: =IF(C33<D33,"UNCOVERED","ok")
A34: Mon | B34: 6:00 PM | C34: =COUNTIF(Schedule!X3:X6,"●")+COUNTIF(Schedule!X3:X6,"R") | D34: =WEEKDAY_STAFF | E34: =IF(C34<D34,"UNCOVERED","ok")
A35: Mon | B35: 6:30 PM | C35: =COUNTIF(Schedule!Y3:Y6,"●")+COUNTIF(Schedule!Y3:Y6,"R") | D35: =WEEKDAY_STAFF | E35: =IF(C35<D35,"UNCOVERED","ok")
A36: Mon | B36: 7:00 PM | C36: =COUNTIF(Schedule!Z3:Z6,"●")+COUNTIF(Schedule!Z3:Z6,"R") | D36: =WEEKDAY_STAFF | E36: =IF(C36<D36,"UNCOVERED","ok")
A37: Mon | B37: 7:30 PM | C37: =COUNTIF(Schedule!AA3:AA6,"●")+COUNTIF(Schedule!AA3:AA6,"R") | D37: =WEEKDAY_STAFF | E37: =IF(C37<D37,"UNCOVERED","ok")
A38: Mon | B38: 8:00 PM | C38: =COUNTIF(Schedule!AB3:AB6,"●")+COUNTIF(Schedule!AB3:AB6,"R") | D38: =WEEKDAY_STAFF | E38: =IF(C38<D38,"UNCOVERED","ok")
A39: Mon | B39: 8:30 PM | C39: =COUNTIF(Schedule!AC3:AC6,"●")+COUNTIF(Schedule!AC3:AC6,"R") | D39: =WEEKDAY_STAFF | E39: =IF(C39<D39,"UNCOVERED","ok")
A40: Mon | B40: 9:00 PM | C40: =COUNTIF(Schedule!AD3:AD6,"●")+COUNTIF(Schedule!AD3:AD6,"R") | D40: =WEEKDAY_STAFF | E40: =IF(C40<D40,"UNCOVERED","ok")
A41: Mon | B41: 9:30 PM | C41: =COUNTIF(Schedule!AE3:AE6,"●")+COUNTIF(Schedule!AE3:AE6,"R") | D41: =WEEKDAY_STAFF | E41: =IF(C41<D41,"UNCOVERED","ok")
A42: Mon | B42: 10:00 PM | C42: =COUNTIF(Schedule!AF3:AF6,"●")+COUNTIF(Schedule!AF3:AF6,"R") | D42: =WEEKDAY_STAFF | E42: =IF(C42<D42,"UNCOVERED","ok")
...
